Workbook

Sheet 使用说明
A1: Omnia Agent v5｜Phase 1 字段母版 V8（SAP ECC v4 recorder evidence 增量） | B1: Omnia Agent v5｜Phase 1 字段母版 V8（SAP ECC v4 recorder evidence 增量） | C1: Omnia Agent v5｜Phase 1 字段母版 V8（SAP ECC v4 recorder evidence 增量） | D1: Omnia Agent v5｜Phase 1 字段母版 V8（SAP ECC v4 recorder evidence 增量） | E1: Omnia Agent v5｜Phase 1 字段母版 V8（SAP ECC v4 recorder evidence 增量） | F1: Omnia Agent v5｜Phase 1 字段母版 V8（SAP ECC v4 recorder evidence 增量） | G1: Omnia Agent v5｜Phase 1 字段母版 V8（SAP ECC v4 recorder evidence 增量） | H1: Omnia Agent v5｜Phase 1 字段母版 V8（SAP ECC v4 recorder evidence 增量）
A3: 母版治理边界
A5: 角色 | B5: 维护内容 | E5: 不得维护/不得假装
A6: 用户/业务负责人 | B6: Omnia 标准字段、必填规则、默认/回退、允许值、Higher/Lower 业务适用性 | E6: 不在母版中维护每次运行的用户实际值
A7: Codex/开发者 | B7: v4 JSON/API/connector/DOM 证据、精确路径、证据状态、校验逻辑 | E7: v4 无证据时不得猜 API、JSON key 或 selector
A8: 运行时 Agent | B8: 从用户上传资料提取需用户提供的值；按本母版规则派生/默认/继承并执行 | E8: 不得要求用户在母版中重复维护每次运行的实际值
A10: Risk–Control 执行模型
A12: 1. 目录存在 | C12: catalog_present_higher/lower 只描述 Omnia 在对应 RAIT 目录中可提供该 Control。
A13: 2. 应建立关联 | C13: link_required_higher/lower 才是 Agent 的执行开关；系统可提供 Control 不等于应关联。
A14: 3. Risk 分类 | C14: classification_higher/lower 分别治理 Higher 与 Lower 下的 Higher/Lower/ClassificationNA/待确认。
A15: 4. 运行时 | C15: 用户新增元素时无需手工逐一关联。录制抓全量目录和代表性关联合同，Agent 按 RAIT 筛选并逐条精确关联、回读验证。
A16: 5. 失败关闭 | C16: 目录缺失、关系端点缺失、assertion 不唯一、隐藏数据策略不满足或无 v4 证据时停止；不得猜测。
A18: 当前母版规模（公式实时统计）
A20: 规范化字段 | C20: Risk-Control 关系 | E20: 正式源字段项 | G20: V4 证据链
A21: =COUNTA(字段母版!$A$5:$A$191) -> 187 | C21: =COUNTA('Risk-Control关系'!$A$5:$A$72) -> 68 | E21: =COUNTIF(原始字段追溯!$E$5:$E$255,"字段") -> 180 | G21: =COUNTA(V4接口证据!$A$5:$A$25) -> 21
A24: 证据状态说明
A26: 已确认-强 | C26: 源码中有精确 route/payload/key/read-back 或明确录制合同。
A27: 部分确认 | C27: 只确认解析/派生/参考目录的一部分；不得扩张为完整写入能力。
A28: 执行阻断 | C28: v4 明确拒绝执行（例如 SAP ECC 内容合同未验证）。
A29: v4未发现/待确认 | C29: v4 未发现足够证据；API/JSON/DOM 列保持空白。

Sheet 字段母版
A1: Phase 1 字段母版
A2: 黄色列由业务维护；蓝色证据列由 Codex/开发者维护。运行时用户实际值不进入本母版。
A4: field_id | B4: Phase | C4: 场景/对象类型 | D4: 对象子类型/区段 | E4: Higher适用 | F4: Lower适用 | G4: Omnia UI标准字段名 | H4: 字段用途 | I4: 填写责任/方式 | J4: 必填规则 | K4: 无资料时默认/回退 | L4: 允许值 | M4: evidence_type | N4: v4 JSON key/path | O4: v4 endpoint+method / connector | P4: 请求/响应位置 | Q4: v4 DOM/selector | R4: v4证据路径+行号 | S4: 证据状态/置信度 | T4: 校验规则 | U4: source_trace_id | V4: 备注
A5: P1.APP.IT.ELEMENT_ID | B5: Phase 1 | C5: Application | E5: Y | F5: Y | G5: ID | H5: 应用程序唯一键，系统必填 | I5: 上传资料提取 | J5: 必填 | K5: APP-金蝶系统 | M5: hybrid | N5: systemInfoRows[].itElementKey|itElementName|itElementNumber; request.number|name | O5: POST /rapr/v0/engagements/{engagementId}/itelement | P5: request: name, number；response: id | R5: src/omnia-phase1.js:656-735; toolkit/tools/gra-creator/src/app.js:4808-4825 | S5: 已确认-强 | T5: 1、是否填写 2、是否与其他活跃元素重名 3、是否与其他回收站内元素重名；AI：1、与之后的risk判断因素中描述的内容是否一致 | U5: SRC.IT元素.007 | V5: 运行时从上传资料提取；创建前执行精确身份预检与重名校验。
A6: P1.APP.IT.ELEMENT_NAME | B6: Phase 1 | C6: Application | E6: Y | F6: Y | G6: 名称 | H6: 可与ID一致，系统必填 | I6: 派生 | J6: 必填 | K6: 与ID一致 | M6: derived | N6: itElementName = element ID | O6: 同 IT Element 创建接口 | P6: request.name | R6: src/domains/omnia/phase1/template-contract.js:98-105; toolkit/tools/gra-creator/src/app.js:4810-4822 | S6: 已确认-强 | U6: SRC.IT元素.008 | V6: 官方 V2 固定派生为元素 ID。
A7: P1.APP.IT.WORKSPACE | B7: Phase 1 | C7: Application | E7: Y | F7: Y | G7: 链接至工作区 | H7: 系统必填 | I7: 上传资料提取 | J7: 必填 | K7: TEST | M7: hybrid | N7: workspaceName -> workspaceFacetId -> request.workspaceId | O7: POST /rapr/v0/engagements/{engagementId}/itelement | P7: request.workspaceId；response.id | R7: src/omnia-phase1.js:673-735; toolkit/tools/gra-creator/src/app.js:4799-4825 | S7: 已确认-强 | T7: 1、工作区填写是否正确；AI：1、若存在与APP名称相似的工作区，可校验ID与工作区是否存在疑似冲突 | U7: SRC.IT元素.009 | V7: 上传资料提供显示名；Agent 解析为精确 facet ID。
A8: P1.APP.IT.DESCRIPTION | B8: Phase 1 | C8: Application | E8: Y | F8: Y | G8: 描述 | H8: 选填 | I8: 派生 | J8: 选填/不适用 | K8: 与ID一致 | M8: derived | N8: itElementDescription -> request.description | O8: POST /rapr/v0/engagements/{engagementId}/itelement | P8: request.description (rich-text editor payload) | R8: src/domains/omnia/phase1/template-contract.js:98-105; toolkit/tools/gra-creator/src/app.js:4818-4822 | S8: 已确认-强 | U8: SRC.IT元素.010 | V8: 官方 V2 固定派生为元素 ID。
A9: P1.APP.IT.IS_RELEVANT | B9: Phase 1 | C9: Application | E9: Y | F9: Y | G9: 与应用程序的相关性 | I9: 派生 | J9: Agent/系统规则驱动 | K9: 不相关 | M9: api | N9: /isRelevant = false | O9: PATCH /rapr/v0/engagements/{engagementId}/itelement/{id} | P9: JSON Patch replace /isRelevant | R9: toolkit/tools/gra-creator/src/it-element-settings.js:1-14; toolkit/tools/gra-creator/src/app.js:4867-4875 | S9: 已确认-强 | U9: SRC.IT元素.011 | V9: v4 固定为 false；Tool 分支不执行此 PATCH。
A10: P1.APP.IT.IS_DATA_AVAILABLE | B10: Phase 1 | C10: Application | E10: Y | F10: Y | G10: IT元素和相关信息技术整体控制(GITC) 将在此约定项目档案的结构化数据中进行测试 | H10: 创建的时候自动开启 | I10: 默认 | J10: Agent/系统规则驱动 | K10: 开启 | L10: 开启|不开启 | M10: api | N10: /isDataAvailable | O10: PATCH /rapr/v0/engagements/{engagementId}/itelement/{id} | P10: JSON Patch replace /isDataAvailable；并带 concurrencyTabId/UpdatedOn | R10: toolkit/tools/gra-creator/src/app.js:4877-4883 | S10: 已确认-强 | U10: SRC.IT元素.012 | V10: v4 输入模板默认 FALSE；原表业务文字“开启”与实际 v4 字段语义需人工确认，不做等同。
A11: P1.APP.IT.GRA_ENTRY | B11: Phase 1 | C11: Application | E11: Y | F11: Y | G11: 添加风险评估GRA | H11: 参见<GRA>-应用程序 | I11: 待确认 | J11: 待确认 | M11: derived | N11: graName/graContentId/typeId/facetId/entityId | O11: POST /rapr/v0/engagements/{engagementId}/riskassessments/create | P11: request creates GRA；response.id/workItemId/referenceNumber | R11: toolkit/tools/gra-creator/src/app.js:4909-4945 | S11: 已确认-强 | U11: SRC.IT元素.013 | V11: 该行是流程入口，不是用户值字段。
A12: P1.APP.IT.MAJOR_CHANGE_THIS_YEAR | B12: Phase 1 | C12: Application | E12: Y | F12: Y | G12: 详细信息-本年度重大修改 | H12: 考虑IT元素在本年度是否已发生重大变化 (例如，系统升级，新系统实施) 或修改。考虑变更的性质和变更的范围。 | I12: 默认 | J12: Agent/系统规则驱动 | K12: 不开启 | L12: 开启|不开启 | M12: source-only | S12: v4未发现/待确认 | U12: SRC.IT元素.014 | V12: v4 未发现可验证的字段级 API/DOM 映射；保留原始规则，不猜测。
A13: P1.APP.IT.SERVICE_ORGANIZATION_SUPPORT | B13: Phase 1 | C13: Application | E13: Y | F13: Y | G13: 详细信息-受到服务机构支持（包括提供的服务，如适用） | H13: 考虑IT元素是否由向该主体提供服务的服务机构 (即，第三方组织或第三方组织的部门) 支持。 | I13: 默认 | J13: Agent/系统规则驱动 | K13: 不开启 | L13: 开启|不开启 | M13: source-only | S13: v4未发现/待确认 | U13: SRC.IT元素.015 | V13: v4 未发现可验证的字段级 API/DOM 映射；保留原始规则，不猜测。
A14: P1.APP.IT.DELOITTE_AUDIT_TOOL | B14: Phase 1 | C14: Application | E14: Y | F14: Y | G14: 详细信息-拟在测试中使用的德勤审计工具 | H14: 考虑在计划的IT元素测试中是否使用任何德勤工具 (如，ACTT)。请注意，在Omnia的当前版本中，位于此处的文件记录可协助您记录及保留有助于计划审计程序的信息，但此信息不会系统地与其他结构化数据链接或相关联。 | I14: 默认 | J14: Agent/系统规则驱动 | K14: 不开启 | L14: 开启|不开启 | M14: source-only | S14: v4未发现/待确认 | U14: SRC.IT元素.016 | V14: v4 未发现可验证的字段级 API/DOM 映射；保留原始规则，不猜测。
A15: P1.APP.IT.BUSINESS_PROCESS | B15: Phase 1 | C15: Application | E15: Y | F15: Y | G15: 业务流程 | H15: 在业务流程图中关联此应用，此处不适用 | I15: 待确认 | J15: 待确认 | M15: source-only | S15: v4未发现/待确认 | U15: SRC.IT元素.017 | V15: v4 未发现可验证的字段级 API/DOM 映射；保留原始规则，不猜测。
A16: P1.DB.IT.ELEMENT_ID | B16: Phase 1 | C16: Database Infrastructure | E16: Y | F16: Y | G16: ID | H16: 数据库基础设施唯一键，系统必填 | I16: 上传资料提取 | J16: 必填 | K16: DB-金蝶系统 | M16: hybrid | N16: systemInfoRows[].itElementKey|itElementName|itElementNumber; request.number|name | O16: POST /rapr/v0/engagements/{engagementId}/itelement | P16: request: name, number；response: id | R16: src/omnia-phase1.js:656-735; toolkit/tools/gra-creator/src/app.js:4808-4825 | S16: 已确认-强 | T16: 1、是否填写 2、是否与其他活跃元素重名 3、是否与其他回收站内元素重名；AI：1、与之后的risk判断因素中描述的内容是否一致 | U16: SRC.IT元素.021 | V16: 运行时从上传资料提取；创建前执行精确身份预检与重名校验。
A17: P1.DB.IT.ELEMENT_NAME | B17: Phase 1 | C17: Database Infrastructure | E17: Y | F17: Y | G17: 名称 | H17: 可与ID一致，系统必填 | I17: 派生 | J17: 必填 | K17: 与ID一致 | M17: derived | N17: itElementName = element ID | O17: 同 IT Element 创建接口 | P17: request.name | R17: src/domains/omnia/phase1/template-contract.js:98-105; toolkit/tools/gra-creator/src/app.js:4810-4822 | S17: 已确认-强 | U17: SRC.IT元素.022 | V17: 官方 V2 固定派生为元素 ID。
A18: P1.DB.IT.WORKSPACE | B18: Phase 1 | C18: Database Infrastructure | E18: Y | F18: Y | G18: 链接至工作区 | H18: 系统必填 | I18: 上传资料提取 | J18: 必填 | K18: TEST | M18: hybrid | N18: workspaceName -> workspaceFacetId -> request.workspaceId | O18: POST /rapr/v0/engagements/{engagementId}/itelement | P18: request.workspaceId；response.id | R18: src/omnia-phase1.js:673-735; toolkit/tools/gra-creator/src/app.js:4799-4825 | S18: 已确认-强 | T18: 1、工作区填写是否正确；AI：1、若存在与名称相似的工作区，可校验ID与工作区是否存在疑似冲突 | U18: SRC.IT元素.023 | V18: 上传资料提供显示名；Agent 解析为精确 facet ID。
A19: P1.DB.IT.DESCRIPTION | B19: Phase 1 | C19: Database Infrastructure | E19: Y | F19: Y | G19: 描述 | H19: 选填 | I19: 派生 | J19: 选填/不适用 | K19: 与ID一致 | M19: derived | N19: itElementDescription -> request.description | O19: POST /rapr/v0/engagements/{engagementId}/itelement | P19: request.description (rich-text editor payload) | R19: src/domains/omnia/phase1/template-contract.js:98-105; toolkit/tools/gra-creator/src/app.js:4818-4822 | S19: 已确认-强 | U19: SRC.IT元素.024 | V19: 官方 V2 固定派生为元素 ID。
A20: P1.DB.IT.IS_RELEVANT | B20: Phase 1 | C20: Database Infrastructure | E20: Y | F20: Y | G20: 与应用程序的相关性 | I20: 派生 | J20: Agent/系统规则驱动 | K20: 不相关 | M20: api | N20: /isRelevant = false | O20: PATCH /rapr/v0/engagements/{engagementId}/itelement/{id} | P20: JSON Patch replace /isRelevant | R20: toolkit/tools/gra-creator/src/it-element-settings.js:1-14; toolkit/tools/gra-creator/src/app.js:4867-4875 | S20: 已确认-强 | U20: SRC.IT元素.025 | V20: v4 固定为 false；Tool 分支不执行此 PATCH。
A21: P1.DB.IT.IS_DATA_AVAILABLE | B21: Phase 1 | C21: Database Infrastructure | E21: Y | F21: Y | G21: IT元素和相关信息技术整体控制(GITC) 将在此约定项目档案的结构化数据中进行测试 | H21: 创建的时候自动开启 | I21: 默认 | J21: Agent/系统规则驱动 | K21: 开启 | L21: 开启|不开启 | M21: api | N21: /isDataAvailable | O21: PATCH /rapr/v0/engagements/{engagementId}/itelement/{id} | P21: JSON Patch replace /isDataAvailable；并带 concurrencyTabId/UpdatedOn | R21: toolkit/tools/gra-creator/src/app.js:4877-4883 | S21: 已确认-强 | U21: SRC.IT元素.026 | V21: v4 输入模板默认 FALSE；原表业务文字“开启”与实际 v4 字段语义需人工确认，不做等同。
A22: P1.DB.IT.GRA_ENTRY | B22: Phase 1 | C22: Database Infrastructure | E22: Y | F22: Y | G22: 添加风险评估GRA | H22: 参见<GRA>-数据库 | I22: 待确认 | J22: 待确认 | M22: derived | N22: graName/graContentId/typeId/facetId/entityId | O22: POST /rapr/v0/engagements/{engagementId}/riskassessments/create | P22: request creates GRA；response.id/workItemId/referenceNumber | R22: toolkit/tools/gra-creator/src/app.js:4909-4945 | S22: 已确认-强 | U22: SRC.IT元素.027 | V22: 该行是流程入口，不是用户值字段。
A23: P1.DB.IT.MAJOR_CHANGE_THIS_YEAR | B23: Phase 1 | C23: Database Infrastructure | E23: Y | F23: Y | G23: 详细信息-本年度重大修改 | H23: 考虑IT元素在本年度是否已发生重大变化 (例如，系统升级，新系统实施) 或修改。考虑变更的性质和变更的范围。 | I23: 默认 | J23: Agent/系统规则驱动 | K23: 不开启 | L23: 开启|不开启 | M23: source-only | S23: v4未发现/待确认 | U23: SRC.IT元素.028 | V23: v4 未发现可验证的字段级 API/DOM 映射；保留原始规则，不猜测。
A24: P1.DB.IT.SERVICE_ORGANIZATION_SUPPORT | B24: Phase 1 | C24: Database Infrastructure | E24: Y | F24: Y | G24: 详细信息-受到服务机构支持（包括提供的服务，如适用） | H24: 考虑IT元素是否由向该主体提供服务的服务机构 (即，第三方组织或第三方组织的部门) 支持。 | I24: 默认 | J24: Agent/系统规则驱动 | K24: 不开启 | L24: 开启|不开启 | M24: source-only | S24: v4未发现/待确认 | U24: SRC.IT元素.029 | V24: v4 未发现可验证的字段级 API/DOM 映射；保留原始规则，不猜测。
A25: P1.DB.IT.DELOITTE_AUDIT_TOOL | B25: Phase 1 | C25: Database Infrastructure | E25: Y | F25: Y | G25: 详细信息-拟在测试中使用的德勤审计工具 | H25: 考虑在计划的IT元素测试中是否使用任何德勤工具 (如，ACTT)。请注意，在Omnia的当前版本中，位于此处的文件记录可协助您记录及保留有助于计划审计程序的信息，但此信息不会系统地与其他结构化数据链接或相关联。 | I25: 默认 | J25: Agent/系统规则驱动 | K25: 不开启 | L25: 开启|不开启 | M25: source-only | S25: v4未发现/待确认 | U25: SRC.IT元素.030 | V25: v4 未发现可验证的字段级 API/DOM 映射；保留原始规则，不猜测。
A26: P1.DB.IT.APPLICATION_RELATION | B26: Phase 1 | C26: Database Infrastructure | E26: Y | F26: Y | G26: 关联应用程序 | H26: 后续创建风险评估受此影响，系统必填 | I26: 上传资料提取 | J26: 必填 | K26: APP-金蝶系统 | M26: api | N26: relationships[].applicationId/infrastructureId | O26: POST /rapr/v0/engagements/{engagementId}/itelement/associate | P26: ItElementId, AssociatingEntityIds[], associationType=InfrastructureApplication, ConcurrencyTabId=602 | R26: toolkit/tools/gra-creator/src/phase1-relationships.js:97-198 | S26: 已确认-强 | T26: 1、是否至少关联一个应用程序 2、工作区是否一致 3、多个应用程序的RAIT是否一致 | U26: SRC.IT元素.031 | V26: 创建基础设施 GRA 前必须建立并双向回读验证。
A27: P1.OS.IT.ELEMENT_ID | B27: Phase 1 | C27: Operating System Infrastructure | E27: Y | F27: Y | G27: ID | H27: 操作系统基础设施唯一键，系统必填 | I27: 上传资料提取 | J27: 必填 | K27: OS-金蝶服务器 | M27: hybrid | N27: systemInfoRows[].itElementKey|itElementName|itElementNumber; request.number|name | O27: POST /rapr/v0/engagements/{engagementId}/itelement | P27: request: name, number；response: id | R27: src/omnia-phase1.js:656-735; toolkit/tools/gra-creator/src/app.js:4808-4825 | S27: 已确认-强 | T27: 1、是否填写 2、是否与其他活跃元素重名 3、是否与其他回收站内元素重名；AI：1、与之后的risk判断因素中描述的内容是否一致 | U27: SRC.IT元素.035 | V27: 运行时从上传资料提取；创建前执行精确身份预检与重名校验。
A28: P1.OS.IT.ELEMENT_NAME | B28: Phase 1 | C28: Operating System Infrastructure | E28: Y | F28: Y | G28: 名称 | H28: 可与ID一致，系统必填 | I28: 派生 | J28: 必填 | K28: 与ID一致 | M28: derived | N28: itElementName = element ID | O28: 同 IT Element 创建接口 | P28: request.name | R28: src/domains/omnia/phase1/template-contract.js:98-105; toolkit/tools/gra-creator/src/app.js:4810-4822 | S28: 已确认-强 | U28: SRC.IT元素.036 | V28: 官方 V2 固定派生为元素 ID。
A29: P1.OS.IT.WORKSPACE | B29: Phase 1 | C29: Operating System Infrastructure | E29: Y | F29: Y | G29: 链接至工作区 | H29: 系统必填 | I29: 上传资料提取 | J29: 必填 | K29: TEST | M29: hybrid | N29: workspaceName -> workspaceFacetId -> request.workspaceId | O29: POST /rapr/v0/engagements/{engagementId}/itelement | P29: request.workspaceId；response.id | R29: src/omnia-phase1.js:673-735; toolkit/tools/gra-creator/src/app.js:4799-4825 | S29: 已确认-强 | T29: 1、工作区填写是否正确；AI：1、若存在与名称相似的工作区，可校验ID与工作区是否存在疑似冲突 | U29: SRC.IT元素.037 | V29: 上传资料提供显示名；Agent 解析为精确 facet ID。
A30: P1.OS.IT.DESCRIPTION | B30: Phase 1 | C30: Operating System Infrastructure | E30: Y | F30: Y | G30: 描述 | H30: 选填；官方V2由Agent固定派生为元素ID | I30: 派生 | J30: 选填/不适用 | K30: 与ID一致 | M30: derived | N30: itElementDescription -> request.description | O30: POST /rapr/v0/engagements/{engagementId}/itelement | P30: request.description (rich-text editor payload) | R30: src/domains/omnia/phase1/template-contract.js:98-105; toolkit/tools/gra-creator/src/app.js:4818-4822 | S30: 已确认-强 | U30: SRC.IT元素.038 | V30: 官方 V2 固定派生为元素 ID。
A31: P1.OS.IT.IS_RELEVANT | B31: Phase 1 | C31: Operating System Infrastructure | E31: Y | F31: Y | G31: 与应用程序的相关性 | I31: 派生 | J31: Agent/系统规则驱动 | K31: 不相关 | M31: api | N31: /isRelevant = false | O31: PATCH /rapr/v0/engagements/{engagementId}/itelement/{id} | P31: JSON Patch replace /isRelevant | R31: toolkit/tools/gra-creator/src/it-element-settings.js:1-14; toolkit/tools/gra-creator/src/app.js:4867-4875 | S31: 已确认-强 | U31: SRC.IT元素.039 | V31: v4 固定为 false；Tool 分支不执行此 PATCH。
A32: P1.OS.IT.IS_DATA_AVAILABLE | B32: Phase 1 | C32: Operating System Infrastructure | E32: Y | F32: Y | G32: IT元素和相关信息技术整体控制(GITC) 将在此约定项目档案的结构化数据中进行测试 | H32: 创建的时候自动开启 | I32: 默认 | J32: Agent/系统规则驱动 | K32: 开启 | L32: 开启|不开启 | M32: api | N32: /isDataAvailable | O32: PATCH /rapr/v0/engagements/{engagementId}/itelement/{id} | P32: JSON Patch replace /isDataAvailable；并带 concurrencyTabId/UpdatedOn | R32: toolkit/tools/gra-creator/src/app.js:4877-4883 | S32: 已确认-强 | U32: SRC.IT元素.040 | V32: v4 输入模板默认 FALSE；原表业务文字“开启”与实际 v4 字段语义需人工确认，不做等同。
A33: P1.OS.IT.GRA_ENTRY | B33: Phase 1 | C33: Operating System Infrastructure | E33: Y | F33: Y | G33: 添加风险评估GRA | H33: 参见<GRA>-操作系统 | I33: 待确认 | J33: 待确认 | M33: derived | N33: graName/graContentId/typeId/facetId/entityId | O33: POST /rapr/v0/engagements/{engagementId}/riskassessments/create | P33: request creates GRA；response.id/workItemId/referenceNumber | R33: toolkit/tools/gra-creator/src/app.js:4909-4945 | S33: 已确认-强 | U33: SRC.IT元素.041 | V33: 该行是流程入口，不是用户值字段。
A34: P1.OS.IT.MAJOR_CHANGE_THIS_YEAR | B34: Phase 1 | C34: Operating System Infrastructure | E34: Y | F34: Y | G34: 详细信息-本年度重大修改 | H34: 考虑IT元素在本年度是否已发生重大变化 (例如，系统升级，新系统实施) 或修改。考虑变更的性质和变更的范围。 | I34: 默认 | J34: Agent/系统规则驱动 | K34: 不开启 | L34: 开启|不开启 | M34: source-only | S34: v4未发现/待确认 | U34: SRC.IT元素.042 | V34: v4 未发现可验证的字段级 API/DOM 映射；保留原始规则，不猜测。
A35: P1.OS.IT.SERVICE_ORGANIZATION_SUPPORT | B35: Phase 1 | C35: Operating System Infrastructure | E35: Y | F35: Y | G35: 详细信息-受到服务机构支持（包括提供的服务，如适用） | H35: 考虑IT元素是否由向该主体提供服务的服务机构 (即，第三方组织或第三方组织的部门) 支持。 | I35: 默认 | J35: Agent/系统规则驱动 | K35: 不开启 | L35: 开启|不开启 | M35: source-only | S35: v4未发现/待确认 | U35: SRC.IT元素.043 | V35: v4 未发现可验证的字段级 API/DOM 映射；保留原始规则，不猜测。
A36: P1.OS.IT.DELOITTE_AUDIT_TOOL | B36: Phase 1 | C36: Operating System Infrastructure | E36: Y | F36: Y | G36: 详细信息-拟在测试中使用的德勤审计工具 | H36: 考虑在计划的IT元素测试中是否使用任何德勤工具 (如，ACTT)。请注意，在Omnia的当前版本中，位于此处的文件记录可协助您记录及保留有助于计划审计程序的信息，但此信息不会系统地与其他结构化数据链接或相关联。 | I36: 默认 | J36: Agent/系统规则驱动 | K36: 不开启 | L36: 开启|不开启 | M36: source-only | S36: v4未发现/待确认 | U36: SRC.IT元素.044 | V36: v4 未发现可验证的字段级 API/DOM 映射；保留原始规则，不猜测。
A37: P1.OS.IT.APPLICATION_RELATION | B37: Phase 1 | C37: Operating System Infrastructure | E37: Y | F37: Y | G37: 关联应用程序 | H37: 后续创建风险评估及RAIT继承受此影响，系统必填 | I37: 上传资料提取 | J37: 必填 | K37: APP-金蝶系统 | M37: api | N37: relationships[].applicationId/infrastructureId | O37: POST /rapr/v0/engagements/{engagementId}/itelement/associate | P37: ItElementId, AssociatingEntityIds[], associationType=InfrastructureApplication, ConcurrencyTabId=602 | R37: toolkit/tools/gra-creator/src/phase1-relationships.js:97-198 | S37: 已确认-强 | T37: 1、是否至少关联一个应用程序 2、工作区是否一致 3、多个应用程序的RAIT是否一致 | U37: SRC.IT元素.045 | V37: 创建基础设施 GRA 前必须建立并双向回读验证。
A38: P1.TOOL.IT.ELEMENT_ID | B38: Phase 1 | C38: IT Tool | E38: Y | F38: Y | G38: ID | H38: 工具唯一键，系统必填 | I38: 上传资料提取 | J38: 必填 | K38: Tool-OA | M38: hybrid | N38: systemInfoRows[].itElementKey|itElementName|itElementNumber; request.number|name | O38: POST /rapr/v0/engagements/{engagementId}/itelement | P38: request: name, number；response: id | R38: src/omnia-phase1.js:656-735; toolkit/tools/gra-creator/src/app.js:4808-4825 | S38: 已确认-强 | T38: 1、是否填写 2、是否与其他活跃元素重名 3、是否与其他回收站内元素重名；AI：1、与之后的risk判断因素中描述的内容是否一致 | U38: SRC.IT元素.050 | V38: 运行时从上传资料提取；创建前执行精确身份预检与重名校验。
A39: P1.TOOL.IT.ELEMENT_NAME | B39: Phase 1 | C39: IT Tool | E39: Y | F39: Y | G39: 名称 | H39: 可与ID一致，系统必填 | I39: 派生 | J39: 必填 | K39: 与ID一致 | M39: derived | N39: itElementName = element ID | O39: 同 IT Element 创建接口 | P39: request.name | R39: src/domains/omnia/phase1/template-contract.js:98-105; toolkit/tools/gra-creator/src/app.js:4810-4822 | S39: 已确认-强 | U39: SRC.IT元素.051 | V39: 官方 V2 固定派生为元素 ID。
A40: P1.TOOL.IT.WORKSPACE | B40: Phase 1 | C40: IT Tool | E40: Y | F40: Y | G40: 链接至工作区 | H40: 系统必填 | I40: 上传资料提取 | J40: 必填 | K40: TEST | M40: hybrid | N40: workspaceName -> workspaceFacetId -> request.workspaceId | O40: POST /rapr/v0/engagements/{engagementId}/itelement | P40: request.workspaceId；response.id | R40: src/omnia-phase1.js:673-735; toolkit/tools/gra-creator/src/app.js:4799-4825 | S40: 已确认-强 | T40: 1、工作区填写是否正确；AI：1、若存在与名称相似的工作区，可校验ID与工作区是否存在疑似冲突 | U40: SRC.IT元素.052 | V40: 上传资料提供显示名；Agent 解析为精确 facet ID。
A41: P1.TOOL.IT.DESCRIPTION | B41: Phase 1 | C41: IT Tool | E41: Y | F41: Y | G41: 描述 | H41: 选填 | I41: 派生 | J41: 选填/不适用 | K41: 与ID一致 | M41: derived | N41: itElementDescription -> request.description | O41: POST /rapr/v0/engagements/{engagementId}/itelement | P41: request.description (rich-text editor payload) | R41: src/domains/omnia/phase1/template-contract.js:98-105; toolkit/tools/gra-creator/src/app.js:4818-4822 | S41: 部分确认 | U41: SRC.IT元素.053 | V41: Tool 创建分支未发送 description；不得声称已写入。
...

Sheet Risk-Control关系
A1: Risk–Control 多对多关系长表
A2: catalog_present_* 仅表示目录存在；link_required_* 决定 Agent 是否应关联。一个 Risk/Control 可出现多行；禁止逗号列表。
A4: relation_id | B4: risk_field_id | C4: Risk标准名 | D4: control_field_id | E4: Control标准名 | F4: 关系类型/方向 | G4: catalog_present_higher | H4: catalog_present_lower | I4: link_required_higher | J4: link_required_lower | K4: classification_higher | L4: classification_lower | M4: 执行适用层级 | N4: 适用场景/对象类型 | O4: 是否必需 | P4: 无资料时策略 | Q4: v4 evidence_type | R4: v4 JSON/API/DOM/connector路径 | S4: 证据文件+行号 | T4: 确认状态 | U4: source_trace_id | V4: 备注
A5: REL.APP.GENERIC.RAITCOR001.APP_01 | B5: P1.RISK.APP.GENERIC.RAITCOR001 | C5: RAITCOR001｜通用应用程序 - 用户拥有的访问权限超出了执行分配的职责所必需的权限，这可能导致职责分离不当。 | D5: P1.CONTROL.APP.GENERIC.APP_01 | E5: APP.01｜管理层批准新用户及变更的用户访问权限的性质与范围，包括标准的应用系统用户组/角色、关键财务报告交易和职责分离。 | F5: Risk -> Control | G5: Y | H5: Y | I5: Y | J5: Y | K5: Higher | L5: Lower | M5: 两者 | N5: Application / 通用应用程序 | O5: 条件必需 | P5: 按元素 RAIT 筛选；目录/端点缺失则停止并报错 | Q5: hybrid | R5: GET plannedresponse + GET controls + POST validateHiddenDataForRiskAssociation + POST controls/controlrisks/associate；connector: association.preflight | S5: src/omnia-phase1.js:1723-1812; toolkit/tools/gra-creator/src/app.js:3700-3865 | T5: 已确认-强 | U5: SRC.风险评估.005 | V5: catalog_present_* 表示目录存在；link_required_* 才决定 Agent 是否建立关联。
A6: REL.APP.GENERIC.RAITCOR001.APP_02 | B6: P1.RISK.APP.GENERIC.RAITCOR001 | C6: RAITCOR001｜通用应用程序 - 用户拥有的访问权限超出了执行分配的职责所必需的权限，这可能导致职责分离不当。 | D6: P1.CONTROL.APP.GENERIC.APP_02 | E6: APP.02｜及时删除或修改已离职和/或调职用户的访问权限。 | F6: Risk -> Control | G6: Y | H6: Y | I6: Y | J6: Y | K6: Higher | L6: Lower | M6: 两者 | N6: Application / 通用应用程序 | O6: 条件必需 | P6: 按元素 RAIT 筛选；目录/端点缺失则停止并报错 | Q6: hybrid | R6: GET plannedresponse + GET controls + POST validateHiddenDataForRiskAssociation + POST controls/controlrisks/associate；connector: association.preflight | S6: src/omnia-phase1.js:1723-1812; toolkit/tools/gra-creator/src/app.js:3700-3865 | T6: 已确认-强 | U6: SRC.风险评估.006 | V6: catalog_present_* 表示目录存在；link_required_* 才决定 Agent 是否建立关联。
A7: REL.APP.GENERIC.RAITCOR001.APP_03 | B7: P1.RISK.APP.GENERIC.RAITCOR001 | C7: RAITCOR001｜通用应用程序 - 用户拥有的访问权限超出了执行分配的职责所必需的权限，这可能导致职责分离不当。 | D7: P1.CONTROL.APP.GENERIC.APP_03 | E7: APP.03｜定期复核用户访问权限。 | F7: Risk -> Control | G7: Y | H7: N | I7: Y | J7: N | K7: Higher | L7: Lower | M7: Higher | N7: Application / 通用应用程序 | O7: 条件必需 | P7: 按元素 RAIT 筛选；目录/端点缺失则停止并报错 | Q7: hybrid | R7: GET plannedresponse + GET controls + POST validateHiddenDataForRiskAssociation + POST controls/controlrisks/associate；connector: association.preflight | S7: src/omnia-phase1.js:1723-1812; toolkit/tools/gra-creator/src/app.js:3700-3865 | T7: 已确认-强 | U7: SRC.风险评估.007 | V7: catalog_present_* 表示目录存在；link_required_* 才决定 Agent 是否建立关联。
A8: REL.APP.GENERIC.RAITCOR001.APP_06 | B8: P1.RISK.APP.GENERIC.RAITCOR001 | C8: RAITCOR001｜通用应用程序 - 用户拥有的访问权限超出了执行分配的职责所必需的权限，这可能导致职责分离不当。 | D8: P1.CONTROL.APP.GENERIC.APP_06 | E8: APP.06｜特权级别访问 (例如安全管理员) 已获得授权并受到适当限制。 | F8: Risk -> Control | G8: Y | H8: Y | I8: Y | J8: Y | K8: Higher | L8: Lower | M8: 两者 | N8: Application / 通用应用程序 | O8: 条件必需 | P8: 按元素 RAIT 筛选；目录/端点缺失则停止并报错 | Q8: hybrid | R8: GET plannedresponse + GET controls + POST validateHiddenDataForRiskAssociation + POST controls/controlrisks/associate；connector: association.preflight | S8: src/omnia-phase1.js:1723-1812; toolkit/tools/gra-creator/src/app.js:3700-3865 | T8: 已确认-强 | U8: SRC.风险评估.008 | V8: catalog_present_* 表示目录存在；link_required_* 才决定 Agent 是否建立关联。
A9: REL.APP.GENERIC.RAITCOR003.APP_05 | B9: P1.RISK.APP.GENERIC.RAITCOR003 | C9: RAITCOR003｜通用应用程序 - 系统配置或更新不足，无法限制正确授权和适当的用户访问系统。 | D9: P1.CONTROL.APP.GENERIC.APP_05 | E9: APP.05｜通过唯一的用户 ID 和密码或其他方法进行身份验证，以此作为验证用户是否有权访问系统的机制。密码参数符合公司和 / 或行业标准 (例如 密码最短长度和复杂度，密码自动过期，账号锁定)。 | F9: Risk -> Control | G9: Y | H9: Y | I9: Y | J9: Y | K9: Higher | L9: Lower | M9: 两者 | N9: Application / 通用应用程序 | O9: 条件必需 | P9: 按元素 RAIT 筛选；目录/端点缺失则停止并报错 | Q9: hybrid | R9: GET plannedresponse + GET controls + POST validateHiddenDataForRiskAssociation + POST controls/controlrisks/associate；connector: association.preflight | S9: src/omnia-phase1.js:1723-1812; toolkit/tools/gra-creator/src/app.js:3700-3865 | T9: 已确认-强 | U9: SRC.风险评估.010 | V9: catalog_present_* 表示目录存在；link_required_* 才决定 Agent 是否建立关联。
A10: REL.APP.GENERIC.RAITCOR004.APP_10 | B10: P1.RISK.APP.GENERIC.RAITCOR004 | C10: RAITCOR004｜通用应用程序 - 对包含相关自动控制 (即可配置设置，自动算法，自动计算和自动数据提取) 和 / 或报告逻辑的应用系统或程序进行了不适当的变更。 | D10: P1.CONTROL.APP.GENERIC.APP_10 | E10: APP.10｜在将应用程序变更移至生产环境之前，应对其进行适当的测试和批准。 | F10: Risk -> Control | G10: Y | H10: Y | I10: Y | J10: Y | K10: Higher | L10: Lower | M10: 两者 | N10: Application / 通用应用程序 | O10: 条件必需 | P10: 按元素 RAIT 筛选；目录/端点缺失则停止并报错 | Q10: hybrid | R10: GET plannedresponse + GET controls + POST validateHiddenDataForRiskAssociation + POST controls/controlrisks/associate；connector: association.preflight | S10: src/omnia-phase1.js:1723-1812; toolkit/tools/gra-creator/src/app.js:3700-3865 | T10: 已确认-强 | U10: SRC.风险评估.011 | V10: catalog_present_* 表示目录存在；link_required_* 才决定 Agent 是否建立关联。
A11: REL.APP.GENERIC.RAITCOR004.APP_13 | B11: P1.RISK.APP.GENERIC.RAITCOR004 | C11: RAITCOR004｜通用应用程序 - 对包含相关自动控制 (即可配置设置，自动算法，自动计算和自动数据提取) 和 / 或报告逻辑的应用系统或程序进行了不适当的变更。 | D11: P1.CONTROL.APP.GENERIC.APP_13 | E11: APP.13｜对应用程序生产环境进行变更的访问受到适当限制，并与开发环境隔离。 | F11: Risk -> Control | G11: Y | H11: Y | I11: Y | J11: Y | K11: Higher | L11: Lower | M11: 两者 | N11: Application / 通用应用程序 | O11: 条件必需 | P11: 按元素 RAIT 筛选；目录/端点缺失则停止并报错 | Q11: hybrid | R11: GET plannedresponse + GET controls + POST validateHiddenDataForRiskAssociation + POST controls/controlrisks/associate；connector: association.preflight | S11: src/omnia-phase1.js:1723-1812; toolkit/tools/gra-creator/src/app.js:3700-3865 | T11: 已确认-强 | U11: SRC.风险评估.012 | V11: catalog_present_* 表示目录存在；link_required_* 才决定 Agent 是否建立关联。
A12: REL.APP.GENERIC.RAITCOR010.DCNO_17 | B12: P1.RISK.APP.GENERIC.RAITCOR010 | C12: RAITCOR010｜通用应用程序 - 当数据丢失时，无法及时恢复或访问财务数据。 | D12: P1.CONTROL.APP.GENERIC.DCNO_17 | E12: DCNO.17｜财务数据定期根据既定的时间表和频率进行备份。 | F12: Risk -> Control | G12: Y | H12: Y | I12: N | J12: N | K12: Higher | L12: Lower | M12: 不建立关联 | N12: Application / 通用应用程序 | O12: N | P12: 按元素 RAIT 筛选；目录/端点缺失则停止并报错 | Q12: hybrid | R12: GET plannedresponse + GET controls + POST validateHiddenDataForRiskAssociation + POST controls/controlrisks/associate；connector: association.preflight | S12: src/omnia-phase1.js:1723-1812; toolkit/tools/gra-creator/src/app.js:3700-3865 | T12: 已确认-强 | U12: SRC.风险评估.014 | V12: catalog_present_* 表示目录存在；link_required_* 才决定 Agent 是否建立关联。
A13: REL.APP.GENERIC.RAITCOR011.APP_15 | B13: P1.RISK.APP.GENERIC.RAITCOR011 | C13: RAITCOR011｜通用应用程序 - 生产系统，程序和 / 或系统任务会导致数据处理不准确，不完整或对数据未经授权的处理。 | D13: P1.CONTROL.APP.GENERIC.APP_15 | E13: APP.15｜只有授权用户才有权变更定时任务调度软件中的批处理任务 (包括接口任务)。 | F13: Risk -> Control | G13: Y | H13: N | I13: Y | J13: N | K13: Higher | L13: Lower | M13: Higher | N13: Application / 通用应用程序 | O13: 条件必需 | P13: 按元素 RAIT 筛选；目录/端点缺失则停止并报错 | Q13: hybrid | R13: GET plannedresponse + GET controls + POST validateHiddenDataForRiskAssociation + POST controls/controlrisks/associate；connector: association.preflight | S13: src/omnia-phase1.js:1723-1812; toolkit/tools/gra-creator/src/app.js:3700-3865 | T13: 已确认-强 | U13: SRC.风险评估.015 | V13: catalog_present_* 表示目录存在；link_required_* 才决定 Agent 是否建立关联。
A14: REL.APP.GENERIC.RAITCOR011.APP_16 | B14: P1.RISK.APP.GENERIC.RAITCOR011 | C14: RAITCOR011｜通用应用程序 - 生产系统，程序和 / 或系统任务会导致数据处理不准确，不完整或对数据未经授权的处理。 | D14: P1.CONTROL.APP.GENERIC.APP_16 | E14: APP.16｜监控关键系统，程序和 / 或任务，并纠正处理错误以确保其成功完成。 | F14: Risk -> Control | G14: Y | H14: N | I14: Y | J14: N | K14: Higher | L14: Lower | M14: Higher | N14: Application / 通用应用程序 | O14: 条件必需 | P14: 按元素 RAIT 筛选；目录/端点缺失则停止并报错 | Q14: hybrid | R14: GET plannedresponse + GET controls + POST validateHiddenDataForRiskAssociation + POST controls/controlrisks/associate；connector: association.preflight | S14: src/omnia-phase1.js:1723-1812; toolkit/tools/gra-creator/src/app.js:3700-3865 | T14: 已确认-强 | U14: SRC.风险评估.016 | V14: catalog_present_* 表示目录存在；link_required_* 才决定 Agent 是否建立关联。
A15: REL.APP.SAP_ECC.RAITCOR011.SAP_15 | B15: P1.RISK.APP.SAP_ECC.RAITCOR011 | C15: RAITCOR011｜SAP ECC - 生产系统、程序和/或系统任务会导致数据处理不准确、不完整或未经授权。 | D15: P1.CONTROL.APP.SAP_ECC.SAP_15 | E15: SAP.15｜只有授权用户有权变更SAP批处理任务（包括接口任务）。 | F15: Risk -> Control | G15: Y | H15: Y | I15: Y | J15: Y | K15: Higher | L15: Lower | M15: 两者 | N15: Application / SAP ECC | O15: 条件必需（按元素 RAIT） | P15: 阻断：不创建、不降级、不猜测 | Q15: v4-recorder-identity+existing-link-readback+user-rule | R15: GET risks/byriskassessmentid -> risk.id/riskNumber/riskRiskScopes[].id；GET controls/byRiskAssessmentId/{id} -> control.id/controlNumber/controlRiskScopes[]；GET plannedresponse/GetPlanResponseDetailByRiskRiskScopeId -> planResponseRisk[0].riskNumber + selected/control[].controlNumber/enabled/currentRiskScopes[].riskId/riskScopeId/assertionType/assertions | S15: v4录制 cfd09224：request-229/seq875（risk list）；request-230/seq881（control list）；request-254/seq985；request-262/seq1021（Higher 既有关联读回） | T15: v4/SAP ECC已证实18/18身份与Higher既有关联读回；关联写入合同可复用；Lower无需单独验证 | U15: SRC.风险评估.022 | V15: 运行时按 riskScopeId/controlId/assertionType/assertion 动态组装并复用 v4 validate+associate 合同。Lower 目标集合取 link_required_lower=Y；无需独立 canary，仍执行幂等检查与写后读回。
... A69: REL.TOOL.IDENTITY.RAITTOOL005.TOOL_06 | B69: P1.RISK.TOOL.IDENTITY.RAITTOOL005 | C69: RAITTOOL005｜身份和访问管理工具 - 用户会被授予不当的访问权限，且/或终止用户的访问权限可能无法及时删除。 | D69: P1.CONTROL.TOOL.IDENTITY.TOOL_06 | E69: TOOL.06｜特权级别访问（如安全管理员或配置修改用户）已获授权并受到适当限制。 | F69: Risk -> Control | G69: Y | H69: Y | I69: Y | J69: Y | K69: Higher | L69: Lower | M69: 两者 | N69: IT Tool / 身份和访问管理工具 | O69: 条件必需 | P69: 按元素 RAIT 筛选；目录/端点缺失则停止并报错 | Q69: hybrid | R69: GET plannedresponse + GET controls + POST validateHiddenDataForRiskAssociation + POST controls/controlrisks/associate；connector: association.preflight | S69: src/omnia-phase1.js:1855-1868; toolkit/tools/gra-creator/src/app.js:3700-3865 | T69: 已确认-强 | U69: SRC.风险评估.129 | V69: catalog_present_* 表示目录存在；link_required_* 才决定 Agent 是否建立关联。
A70: REL.TOOL.IDENTITY.RAITTOOL005.TOOL_10 | B70: P1.RISK.TOOL.IDENTITY.RAITTOOL005 | C70: RAITTOOL005｜身份和访问管理工具访问授权风险 | D70: P1.CONTROL.TOOL.IDENTITY.TOOL_10 | E70: TOOL.10｜v4未发现标准中文名/待确认 | F70: Risk -> Control | G70: Y | H70: N | I70: Y | J70: N | K70: Higher | L70: Lower | M70: Higher | N70: IT Tool / 身份和访问管理工具 | O70: 条件必需 | P70: 按元素 RAIT 筛选；目录缺失则停止并报错 | Q70: derived | R70: toolScopedDefaults -> ControlLinks；GET controls + POST controls/controlrisks/associate | S70: src/omnia-phase1.js:1855-1868; toolkit/tools/gra-creator/src/app.js:3700-3865 | T70: 已确认-强 | V70: 来自 v4 录制合同；原表无标准中文名，明确待确认，不补猜。
A71: REL.TOOL.IDENTITY.RAITTOOL005.TOOL_01 | B71: P1.RISK.TOOL.IDENTITY.RAITTOOL005 | C71: RAITTOOL005｜身份和访问管理工具访问授权风险 | D71: P1.CONTROL.TOOL.IDENTITY.TOOL_01 | E71: TOOL.01｜v4未发现标准中文名/待确认 | F71: Risk -> Control | G71: Y | H71: N | I71: Y | J71: N | K71: Higher | L71: Lower | M71: Higher | N71: IT Tool / 身份和访问管理工具 | O71: 条件必需 | P71: 按元素 RAIT 筛选；目录缺失则停止并报错 | Q71: derived | R71: toolScopedDefaults -> ControlLinks；GET controls + POST controls/controlrisks/associate | S71: src/omnia-phase1.js:1855-1868; toolkit/tools/gra-creator/src/app.js:3700-3865 | T71: 已确认-强 | V71: 来自 v4 录制合同；原表无标准中文名，明确待确认，不补猜。
A72: REL.TOOL.IDENTITY.RAITTOOL005.TOOL_02 | B72: P1.RISK.TOOL.IDENTITY.RAITTOOL005 | C72: RAITTOOL005｜身份和访问管理工具访问授权风险 | D72: P1.CONTROL.TOOL.IDENTITY.TOOL_02 | E72: TOOL.02｜v4未发现标准中文名/待确认 | F72: Risk -> Control | G72: Y | H72: N | I72: Y | J72: N | K72: Higher | L72: Lower | M72: Higher | N72: IT Tool / 身份和访问管理工具 | O72: 条件必需 | P72: 按元素 RAIT 筛选；目录缺失则停止并报错 | Q72: derived | R72: toolScopedDefaults -> ControlLinks；GET controls + POST controls/controlrisks/associate | S72: src/omnia-phase1.js:1855-1868; toolkit/tools/gra-creator/src/app.js:3700-3865 | T72: 已确认-强 | V72: 来自 v4 录制合同；原表无标准中文名，明确待确认，不补猜。

Sheet V4接口证据
A1: V4 接口与录制证据
A2: 一条真实链路一行。API、DOM、connector、recording 分开标注；浏览器会话内 fetch 不伪装成纯后端 SDK。
A4: evidence_id | B4: operation | C4: evidence_type | D4: endpoint/method/connector operation | E4: payload/response/DOM | F4: 调用入口 | G4: 证据位置 | H4: 适用功能 | I4: 确认状态 | J4: 置信说明 | K4: 备注
A5: EV.P1.UPLOAD_PARSE | B5: 上传资料解析 | C5: derived | D5: 官方 V2 分区解析 | E5: systemInfoRows[] / relationships[] | F5: 读取 Excel 分区字段、校验必填/枚举并建立稳定关系键 | G5: src/omnia-phase1.js:656-768 | H5: 字段导入 | I5: 已确认-强 | J5: 精确 route、payload、read-back 或明确源码合同 | K5: 用户值仅运行时提取
A6: EV.P1.DERIVE | B6: 名称/描述派生 | C6: derived | D6: phase1OfficialDerivedValues | E6: graName=GRA-{id}; description=id | F6: 固定派生，不要求用户重复维护 | G6: src/domains/omnia/phase1/template-contract.js:98-105 | H6: IT Element/GRA | I6: 已确认-强 | J6: 精确 route、payload、read-back 或明确源码合同
A7: EV.P1.PAGE_FETCH | B7: 浏览器会话内 API | C7: hybrid | D7: page.evaluate(fetch) | E7: credentials=include; captured authorization; JSON response | F7: GET/POST/PATCH 均通过绑定 Omnia 页面会话执行 | G7: toolkit/tools/gra-creator/src/app.js:1340-1420 | H7: 所有 Phase1 API | I7: 已确认-强 | J7: 精确 route、payload、read-back 或明确源码合同 | K7: 不是 DOM 表单写入
A8: EV.P1.CREATE_ELEMENT | B8: 新建 IT Element | C8: api | D8: POST /rapr/v0/engagements/{engagementId}/itelement | E8: name, workspaceId, engagementId, number, description/itElementType/typeId；response.id | F8: createOneGra | G8: toolkit/tools/gra-creator/src/app.js:4808-4825 | H8: APP/DB/OS/Tool | I8: 已确认-强 | J8: 精确 route、payload、read-back 或明确源码合同 | K8: Tool 分支不含 description
A9: EV.P1.EDIT_SETTINGS | B9: 编辑 IT Element 设置 | C9: api | D9: PATCH /rapr/v0/engagements/{engagementId}/itelement/{id} | E9: JSON Patch /typeId,/isRelevant,/isDataAvailable + concurrency | F9: 创建后设置 | G9: toolkit/tools/gra-creator/src/it-element-settings.js:1-14; toolkit/tools/gra-creator/src/app.js:4867-4883 | H9: APP/DB/OS | I9: 已确认-强 | J9: 精确 route、payload、read-back 或明确源码合同 | K9: Tool 不适用
A10: EV.P1.ASSOC_INFRA_APP | B10: 关联 Infrastructure-Application | C10: api | D10: POST .../itelement/associate | E10: ItElementId, AssociatingEntityIds[], associationType=InfrastructureApplication, ConcurrencyTabId=602；双向搜索回读 | F10: 基础设施 GRA 创建前 | G10: toolkit/tools/gra-creator/src/phase1-relationships.js:97-198 | H10: DB/OS 与 APP | I10: 已确认-强 | J10: 精确 route、payload、read-back 或明确源码合同
A11: EV.P1.ASSOC_TOOL | B11: 关联 Tool-Element | C11: api | D11: POST .../itelement/associate | E11: associationType=ItToolApplication/ItToolInfrastructure; concurrency 802/803；回读 | F11: Tool 后处理 | G11: toolkit/tools/gra-creator/src/phase1-relationships.js:201-288 | H11: Tool 与 APP/Infrastructure | I11: 已确认-强 | J11: 精确 route、payload、read-back 或明确源码合同
A12: EV.P1.CREATE_GRA | B12: 新建 GRA | C12: api | D12: POST /rapr/v0/engagements/{engagementId}/riskassessments/create | E12: inkContentId,typeId,facetId,entityId,name；response id/workItemId/referenceNumber | F12: createOneGra | G12: toolkit/tools/gra-creator/src/app.js:4909-4945 | H12: GRA | I12: 已确认-强 | J12: 精确 route、payload、read-back 或明确源码合同
A13: EV.P1.RENAME_GRA | B13: 编辑 GRA 名称 | C13: api | D13: PATCH .../riskassessments/{id} | E13: JSON Patch /name | F13: 创建内容后 | G13: toolkit/tools/gra-creator/src/app.js:4960-4965 | H13: GRA | I13: 已确认-强 | J13: 精确 route、payload、read-back 或明确源码合同
A14: EV.P1.RISK_FACTORS | B14: 读取/编辑 Risk Factors | C14: api | D14: GET .../risk-factors/byRiskAssessmentId/{id}; PATCH categories/factors/{id} | E14: riskFactors[]; /applicable=true; /riskLevel | F14: GRA 评价 | G14: toolkit/tools/gra-creator/src/app.js:4968-4996 | H14: Risk factors | I14: 已确认-强 | J14: 精确 route、payload、read-back 或明确源码合同
A15: EV.P1.RAIT | B15: 编辑并回读 RAIT | C15: api | D15: PATCH + GET .../riskassessments/{id} | E15: JSON Patch /status=EvaluationStarted,/itElementRaitConclusionLevelId；GET read-back | F15: GRA 评价 | G15: toolkit/tools/gra-creator/src/app.js:4999-5023 | H15: RAIT | I15: 已确认-强 | J15: 精确 route、payload、read-back 或明确源码合同
A16: EV.P1.SUBMIT | B16: 提交评价 | C16: api | D16: POST .../submit-riskfactor-evaluation?skipValidation=false | E16: riskLevelOverride,isPurgeControlHiddenData,updateQM,accountContents；poll status=EvaluationComplete | F16: GRA 评价 | G16: toolkit/tools/gra-creator/src/app.js:5025-5049 | H16: GRA | I16: 已确认-强 | J16: 精确 route、payload、read-back 或明确源码合同
A17: EV.P1.READ_CATALOG | B17: 读取 Risk/Control 目录 | C17: api | D17: GET plannedresponse/byRiskAssessmentId；GET controls/byRiskAssessmentId | E17: plannedResponses[]; controls[] | F17: Risk-Control 后处理 | G17: toolkit/tools/gra-creator/src/app.js:3199-3251,3354-3400 | H17: Risk/Control | I17: 已确认-强 | J17: 精确 route、payload、read-back 或明确源码合同
A18: EV.P1.RISK_CLASS | B18: 设置 Risk 分类 | C18: api | D18: PATCH /rapr/v0/engagements/{engagementId}/risks/{risk.id} | E18: JSON Patch /classificationType with optional /updatedOn test | F18: Risk 后处理 | G18: toolkit/tools/gra-creator/src/app.js:5134-5145 | H18: Risk | I18: 已确认-强 | J18: 精确 route、payload、read-back 或明确源码合同
A19: EV.P1.LINK_VALIDATE | B19: Risk-Control 关联预检 | C19: api | D19: POST .../controls/validateHiddenDataForRiskAssociation | E19: riskId, operation=AddAssociation, controlIds[] | F19: associateGraControlLinks | G19: toolkit/tools/gra-creator/src/app.js:3797-3813 | H19: Risk-Control | I19: 已确认-强 | J19: 精确 route、payload、read-back 或明确源码合同 | K19: purgeHiddenData 受响应约束
A20: EV.P1.LINK_WRITE | B20: Risk-Control 建立关联 | C20: api | D20: POST .../controls/controlrisks/associate | E20: controlRiskScopes[{controlId,riskScopeId,assertionType,riskId,assertions[]}],riskId,updatedOn,isPurgeControlHiddenData | F20: associateGraControlLinks | G20: toolkit/tools/gra-creator/src/app.js:3814-3854 | H20: Risk-Control | I20: 已确认-强 | J20: 精确 route、payload、read-back 或明确源码合同 | K20: 写后轮询 detail 验证
A21: EV.P1.CONNECTOR_READ | B21: Connector 只读接口 | C21: connector | D21: engagement.inspect / controls-directory / association.preflight | E21: 输入 schema 与 handler 映射 | F21: Connector toolkit | G21: connector/src/toolkit-modules/audit-risk.js:9-29,70-100,207-224 | H21: 目录/预检 | I21: 已确认-强 | J21: 精确 route、payload、read-back 或明确源码合同 | K21: effect=read
A22: EV.P1.DELETE_GRA | B22: 删除 GRA | C22: api | D22: PATCH .../riskassessments/{id}/softdelete | E22: 无通用 body；白名单路由并回读回收站状态 | F22: Gateway delete workflow | G22: connector/src/omnia-gateway.js:47-55,5392-5410 | H22: GRA 删除 | I22: 已确认-强 | J22: 精确 route、payload、read-back 或明确源码合同 | K22: 独立删除合同
A23: EV.P1.DELETE_ELEMENT | B23: 删除 IT Element | C23: api | D23: PATCH .../itelement/{id}/softdelete | E23: 按 APP/DB/OS/Tool 独立授权；依赖预检/必要时 disassociate | F23: Gateway delete workflow | G23: connector/src/omnia-gateway.js:53-80,4156,4449,4500 | H23: IT Element 删除 | I23: 已确认-强 | J23: 精确 route、payload、read-back 或明确源码合同 | K23: 软删除
A24: EV.P1.RECORD_NETWORK | B24: 录制网络合同 | C24: recording | D24: CDP Network.requestWillBeSent/responseReceived/getResponseBody | E24: method,url,requestBody,responseBody；过滤敏感头和值 | F24: Omnia Recorder | G24: connector/src/omnia-recorder.js:1042-1085,1088-1264 | H24: API 契约录制 | I24: 已确认-强 | J24: 精确 route、payload、read-back 或明确源码合同 | K24: 录全量目录+代表性关联
A25: EV.P1.RECORD_DOM | B25: 录制 DOM 交互 | C25: dom | D25: 通用 nth-of-type selector（最多 5 层） | E25: action,selector,tag,type,role,ariaLabel,buttonLabel；敏感输入不记录 | F25: Omnia Recorder interaction instrumentation | G25: connector/src/omnia-recorder.js:47-130 | H25: DOM 交互证据 | I25: 已确认-强 | J25: 精确 route、payload、read-back 或明确源码合同 | K25: 不是字段级稳定 selector；字段映射不得伪装成 DOM

Sheet 规则与枚举
A1: 规则与枚举
A2: 默认值、允许值、必填逻辑和回退策略集中治理；字段母版仅呈现字段级结果，若冲突以本表经确认规则为准。
A4: rule_id | B4: 治理键 | C4: 规则类型 | D4: 适用字段/对象 | E4: 默认/枚举/逻辑 | F4: 无资料时回退/阻断策略 | G4: 依据 | H4: 确认状态
A5: RULE.P1.RUNTIME.USER_VALUES | B5: runtime.user_values | C5: 职责边界 | D5: 所有用户实际值 | E5: 仅在运行时由 Agent 从用户上传资料提取；母版不维护实际用户值 | F5: 无资料时按字段规则默认/回退；无策略则阻断 | G5: 用户判断 | H5: 已确认
A6: RULE.P1.APP.SUBTYPE | B6: APP.subtype | C6: 枚举 | D6: APP 类型 | E6: Generic|SAP ECC | F6: SAP ECC 执行阻断，不得降级为 Generic | G6: src/omnia-phase1.js:1048-1061 | H6: 已确认
A7: RULE.P1.DB.SUBTYPE | B7: DB.subtype | C7: 枚举 | D7: DB 类型 | E7: Generic|Oracle|SQL | F7: 无匹配则阻断 | G7: src/domains/omnia/phase1/template-contract.js:27-35 | H7: 已确认
A8: RULE.P1.OS.SUBTYPE | B8: OS.subtype | C8: 枚举 | D8: OS 类型 | E8: Generic|UNIX|WIN | F8: 无匹配则阻断 | G8: src/domains/omnia/phase1/template-contract.js:37-45 | H8: 已确认
A9: RULE.P1.TOOL.SUBTYPE | B9: TOOL.subtype | C9: 枚举 | D9: Tool 类型 | E9: 工单工具|身份和访问管理工具 | F9: 无录制合同则阻断 | G9: src/omnia-phase1.js:1855-1868 | H9: 已确认
A10: RULE.P1.RAIT | B10: GRA.rait | C10: 枚举 | D10: APP/Tool RAIT | E10: Higher|Lower | F10: 缺失/非法则阻断 | G10: src/omnia-phase1.js:701-708 | H10: 已确认
A11: RULE.P1.INFRA.RAIT | B11: INFRA.rait | C11: 继承 | D11: DB/OS RAIT | E11: 从所有关联 APP 的真实 GRA 回读继承且必须一致 | F11: 缺关联、不可读或不一致则阻断 | G11: src/omnia-phase1.js:1026-1045 | H11: 已确认
A12: RULE.P1.GRA.NAME | B12: GRA.name | C12: 派生 | D12: GRA 名称 | E12: GRA-{元素ID} | F12: 重名则阻断 | G12: src/domains/omnia/phase1/template-contract.js:98-105 | H12: 已确认
A13: RULE.P1.ELEMENT.NAME | B13: ITElement.name | C13: 派生 | D13: 元素名称 | E13: 与元素ID一致 | F13: ID缺失则阻断 | G13: src/domains/omnia/phase1/template-contract.js:98-105 | H13: 已确认
A14: RULE.P1.ELEMENT.RELEVANCE | B14: ITElement.isRelevant | C14: 默认 | D14: 与应用程序的相关性 | E14: FALSE/不相关 | F14: 非 Tool；PATCH 后回读 | G14: toolkit/tools/gra-creator/src/it-element-settings.js:1-14 | H14: 已确认
A15: RULE.P1.ELEMENT.DATA | B15: ITElement.isDataAvailable | C15: 默认 | D15: 数据可用性 | E15: FALSE | F15: 原表业务文字“开启”与 API 字段语义不等同，待业务确认 | G15: toolkit/tools/gra-creator/src/app.js:4877-4883 | H15: 部分确认
... A26: RULE.P1.GRA.SCORE.LOWER.ONE | B26: GRA.score.lower | C26: 动态评分 | D26: 每个适用评分项 | E26: Lower -> 1（仅 applicable=true 且 1 ∈ riskLevelSpectrum[].value） | F26: 15项运行时元数据均允许1；Lower 复用同一风险评分 PATCH 合同，所有 applicable=true 项写1，无需单独 Lower canary。 | G26: v4录制 cfd09224：riskFactors metadata request-180/seq677；Lower无写入事件 | H26: Lower按运行时 riskLevelSpectrum 选择 value=1，逐项写入并读回；不硬编码对象 ID

Sheet 覆盖与质检
A1: 覆盖与质检｜公式驱动
A2: 必填且来自上传资料、无默认值是合法策略；只有既无默认/回退又无明确上传/派生/继承/默认/自动策略时才报错。
A4: 指标 | B4: 公式结果 | D4: 证据状态 | E4: 字段数
A5: 正式源字段项 | B5: =COUNTIF(原始字段追溯!$E$5:$E$255,"字段") -> 180 | D5: 已确认-强 | E5: =COUNTIF(字段母版!$S$5:$S$191,D5) -> 137
A6: 已映射源字段项 | B6: =COUNTIFS(原始字段追溯!$E$5:$E$255,"字段",原始字段追溯!$N$5:$N$255,"<>") -> 180 | D6: 已确认-中 | E6: =COUNTIF(字段母版!$S$5:$S$191,D6) -> 0
A7: 源字段覆盖率 | B7: =IF(B5=0,0,B6/B5) -> 1 | D7: 已确认-弱 | E7: =COUNTIF(字段母版!$S$5:$S$191,D7) -> 0
A8: 规范化字段数 | B8: =COUNTA(字段母版!$A$5:$A$191) -> 187 | D8: 部分确认 | E8: =COUNTIF(字段母版!$S$5:$S$191,D8) -> 27
A9: Risk-Control 关系数 | B9: =COUNTA('Risk-Control关系'!$A$5:$A$72) -> 68 | D9: 执行阻断 | E9: =COUNTIF(字段母版!$S$5:$S$191,D9) -> 0
A10: 已确认强证据链 | B10: =COUNTIF(V4接口证据!$I$5:$I$25,"已确认-强") -> 21 | D10: v4未发现/待确认 | E10: =COUNTIF(字段母版!$S$5:$S$191,D10) -> 13
A11: 待确认/部分/阻断字段 | B11: =COUNTIF(字段母版!$S$5:$S$191,"v4未发现/待确认")+COUNTIF(字段母版!$S$5:$S$191,"部分确认")+COUNTIF(字段母版!$S$5:$S$191,"执行阻断") -> 40 | D11: 不适用 | E11: =COUNTIF(字段母版!$S$5:$S$191,D11) -> 2
A14: 源字段覆盖缺口
A15: trace_item_id | B15: 源位置 | C15: 源字段 | D15: 问题
A16: =IF(AND(原始字段追溯!$E$5="字段",原始字段追溯!$N$5=""),原始字段追溯!$A$5,"") | B16: =IF(A16="","",原始字段追溯!$C$5&"!"&原始字段追溯!$D$5) | C16: =IF(A16="","",原始字段追溯!$H$5) | D16: =IF(A16="","","正式源字段未映射")
A17: =IF(AND(原始字段追溯!$E$6="字段",原始字段追溯!$N$6=""),原始字段追溯!$A$6,"") | B17: =IF(A17="","",原始字段追溯!$C$6&"!"&原始字段追溯!$D$6) | C17: =IF(A17="","",原始字段追溯!$H$6) | D17: =IF(A17="","","正式源字段未映射")
A18: =IF(AND(原始字段追溯!$E$7="字段",原始字段追溯!$N$7=""),原始字段追溯!$A$7,"") | B18: =IF(A18="","",原始字段追溯!$C$7&"!"&原始字段追溯!$D$7) | C18: =IF(A18="","",原始字段追溯!$H$7) | D18: =IF(A18="","","正式源字段未映射")
A19: =IF(AND(原始字段追溯!$E$8="字段",原始字段追溯!$N$8=""),原始字段追溯!$A$8,"") | B19: =IF(A19="","",原始字段追溯!$C$8&"!"&原始字段追溯!$D$8) | C19: =IF(A19="","",原始字段追溯!$H$8) | D19: =IF(A19="","","正式源字段未映射")
A20: =IF(AND(原始字段追溯!$E$9="字段",原始字段追溯!$N$9=""),原始字段追溯!$A$9,"") | B20: =IF(A20="","",原始字段追溯!$C$9&"!"&原始字段追溯!$D$9) | C20: =IF(A20="","",原始字段追溯!$H$9) | D20: =IF(A20="","","正式源字段未映射")
A21: =IF(AND(原始字段追溯!$E$10="字段",原始字段追溯!$N$10=""),原始字段追溯!$A$10,"") | B21: =IF(A21="","",原始字段追溯!$C$10&"!"&原始字段追溯!$D$10) | C21: =IF(A21="","",原始字段追溯!$H$10) | D21: =IF(A21="","","正式源字段未映射")
A22: =IF(AND(原始字段追溯!$E$11="字段",原始字段追溯!$N$11=""),原始字段追溯!$A$11,"") | B22: =IF(A22="","",原始字段追溯!$C$11&"!"&原始字段追溯!$D$11) | C22: =IF(A22="","",原始字段追溯!$H$11) | D22: =IF(A22="","","正式源字段未映射")
A23: =IF(AND(原始字段追溯!$E$12="字段",原始字段追溯!$N$12=""),原始字段追溯!$A$12,"") | B23: =IF(A23="","",原始字段追溯!$C$12&"!"&原始字段追溯!$D$12) | C23: =IF(A23="","",原始字段追溯!$H$12) | D23: =IF(A23="","","正式源字段未映射")
A24: =IF(AND(原始字段追溯!$E$13="字段",原始字段追溯!$N$13=""),原始字段追溯!$A$13,"") | B24: =IF(A24="","",原始字段追溯!$C$13&"!"&原始字段追溯!$D$13) | C24: =IF(A24="","",原始字段追溯!$H$13) | D24: =IF(A24="","","正式源字段未映射")
A25: =IF(AND(原始字段追溯!$E$14="字段",原始字段追溯!$N$14=""),原始字段追溯!$A$14,"") | B25: =IF(A25="","",原始字段追溯!$C$14&"!"&原始字段追溯!$D$14) | C25: =IF(A25="","",原始字段追溯!$H$14) | D25: =IF(A25="","","正式源字段未映射")
A26: =IF(AND(原始字段追溯!$E$15="字段",原始字段追溯!$N$15=""),原始字段追溯!$A$15,"") | B26: =IF(A26="","",原始字段追溯!$C$15&"!"&原始字段追溯!$D$15) | C26: =IF(A26="","",原始字段追溯!$H$15) | D26: =IF(A26="","","正式源字段未映射")
A27: =IF(AND(原始字段追溯!$E$16="字段",原始字段追溯!$N$16=""),原始字段追溯!$A$16,"") | B27: =IF(A27="","",原始字段追溯!$C$16&"!"&原始字段追溯!$D$16) | C27: =IF(A27="","",原始字段追溯!$H$16) | D27: =IF(A27="","","正式源字段未映射")
A28: =IF(AND(原始字段追溯!$E$17="字段",原始字段追溯!$N$17=""),原始字段追溯!$A$17,"") | B28: =IF(A28="","",原始字段追溯!$C$17&"!"&原始字段追溯!$D$17) | C28: =IF(A28="","",原始字段追溯!$H$17) | D28: =IF(A28="","","正式源字段未映射")
A29: =IF(AND(原始字段追溯!$E$18="字段",原始字段追溯!$N$18=""),原始字段追溯!$A$18,"") | B29: =IF(A29="","",原始字段追溯!$C$18&"!"&原始字段追溯!$D$18) | C29: =IF(A29="","",原始字段追溯!$H$18) | D29: =IF(A29="","","正式源字段未映射")
A30: =IF(AND(原始字段追溯!$E$19="字段",原始字段追溯!$N$19=""),原始字段追溯!$A$19,"") | B30: =IF(A30="","",原始字段追溯!$C$19&"!"&原始字段追溯!$D$19) | C30: =IF(A30="","",原始字段追溯!$H$19) | D30: =IF(A30="","","正式源字段未映射")
A31: =IF(AND(原始字段追溯!$E$20="字段",原始字段追溯!$N$20=""),原始字段追溯!$A$20,"") | B31: =IF(A31="","",原始字段追溯!$C$20&"!"&原始字段追溯!$D$20) | C31: =IF(A31="","",原始字段追溯!$H$20) | D31: =IF(A31="","","正式源字段未映射")
A32: =IF(AND(原始字段追溯!$E$21="字段",原始字段追溯!$N$21=""),原始字段追溯!$A$21,"") | B32: =IF(A32="","",原始字段追溯!$C$21&"!"&原始字段追溯!$D$21) | C32: =IF(A32="","",原始字段追溯!$H$21) | D32: =IF(A32="","","正式源字段未映射")
A33: =IF(AND(原始字段追溯!$E$22="字段",原始字段追溯!$N$22=""),原始字段追溯!$A$22,"") | B33: =IF(A33="","",原始字段追溯!$C$22&"!"&原始字段追溯!$D$22) | C33: =IF(A33="","",原始字段追溯!$H$22) | D33: =IF(A33="","","正式源字段未映射")
A34: =IF(AND(原始字段追溯!$E$23="字段",原始字段追溯!$N$23=""),原始字段追溯!$A$23,"") | B34: =IF(A34="","",原始字段追溯!$C$23&"!"&原始字段追溯!$D$23) | C34: =IF(A34="","",原始字段追溯!$H$23) | D34: =IF(A34="","","正式源字段未映射")
A35: =IF(AND(原始字段追溯!$E$24="字段",原始字段追溯!$N$24=""),原始字段追溯!$A$24,"") | B35: =IF(A35="","",原始字段追溯!$C$24&"!"&原始字段追溯!$D$24) | C35: =IF(A35="","",原始字段追溯!$H$24) | D35: =IF(A35="","","正式源字段未映射")
A36: =IF(AND(原始字段追溯!$E$25="字段",原始字段追溯!$N$25=""),原始字段追溯!$A$25,"") | B36: =IF(A36="","",原始字段追溯!$C$25&"!"&原始字段追溯!$D$25) | C36: =IF(A36="","",原始字段追溯!$H$25) | D36: =IF(A36="","","正式源字段未映射")
A37: =IF(AND(原始字段追溯!$E$26="字段",原始字段追溯!$N$26=""),原始字段追溯!$A$26,"") | B37: =IF(A37="","",原始字段追溯!$C$26&"!"&原始字段追溯!$D$26) | C37: =IF(A37="","",原始字段追溯!$H$26) | D37: =IF(A37="","","正式源字段未映射")
A38: =IF(AND(原始字段追溯!$E$27="字段",原始字段追溯!$N$27=""),原始字段追溯!$A$27,"") | B38: =IF(A38="","",原始字段追溯!$C$27&"!"&原始字段追溯!$D$27) | C38: =IF(A38="","",原始字段追溯!$H$27) | D38: =IF(A38="","","正式源字段未映射")
A39: =IF(AND(原始字段追溯!$E$28="字段",原始字段追溯!$N$28=""),原始字段追溯!$A$28,"") | B39: =IF(A39="","",原始字段追溯!$C$28&"!"&原始字段追溯!$D$28) | C39: =IF(A39="","",原始字段追溯!$H$28) | D39: =IF(A39="","","正式源字段未映射")
A40: =IF(AND(原始字段追溯!$E$29="字段",原始字段追溯!$N$29=""),原始字段追溯!$A$29,"") | B40: =IF(A40="","",原始字段追溯!$C$29&"!"&原始字段追溯!$D$29) | C40: =IF(A40="","",原始字段追溯!$H$29) | D40: =IF(A40="","","正式源字段未映射")
A41: =IF(AND(原始字段追溯!$E$30="字段",原始字段追溯!$N$30=""),原始字段追溯!$A$30,"") | B41: =IF(A41="","",原始字段追溯!$C$30&"!"&原始字段追溯!$D$30) | C41: =IF(A41="","",原始字段追溯!$H$30) | D41: =IF(A41="","","正式源字段未映射")
A42: =IF(AND(原始字段追溯!$E$31="字段",原始字段追溯!$N$31=""),原始字段追溯!$A$31,"") | B42: =IF(A42="","",原始字段追溯!$C$31&"!"&原始字段追溯!$D$31) | C42: =IF(A42="","",原始字段追溯!$H$31) | D42: =IF(A42="","","正式源字段未映射")
A43: =IF(AND(原始字段追溯!$E$32="字段",原始字段追溯!$N$32=""),原始字段追溯!$A$32,"") | B43: =IF(A43="","",原始字段追溯!$C$32&"!"&原始字段追溯!$D$32) | C43: =IF(A43="","",原始字段追溯!$H$32) | D43: =IF(A43="","","正式源字段未映射")
...

Sheet 原始字段追溯
A1: 原始字段追溯
A2: 每个正式源字段项映射到一个 master_field_id；同一原始行同时含 Risk 与 Control 时拆成两条追溯项，不用逗号列表。结构行也保留以便审计。
A4: trace_item_id | B4: source_file | C4: source_sheet | D4: source_row | E4: 行角色 | F4: 源对象类型 | G4: 源区段/子类型 | H4: 源字段/编号 | I4: 原始描述/汇总 | J4: 原始填写方式/评估 | K4: 原始示例/关系 | L4: 原始Higher/非AI校验 | M4: 原始Lower/AI校验 | N4: master_field_id | O4: 追溯状态 | P4: 备注
A5: SRC.IT元素.001 | B5: omnia agent字段对照文档-补全.xlsx | C5: IT元素 | D5: 1 | E5: 结构/说明 | G5: IT元素 | H5: 备注 | O5: 不适用 | P5: 原始文本逐项保留；未改变原意。
A6: SRC.IT元素.002 | B6: omnia agent字段对照文档-补全.xlsx | C6: IT元素 | D6: 2 | E6: 结构/说明 | G6: IT元素 | H6: 名称以中文版Omnia显示的字段优先 | O6: 不适用 | P6: 原始文本逐项保留；未改变原意。
A7: SRC.IT元素.003 | B7: omnia agent字段对照文档-补全.xlsx | C7: IT元素 | D7: 3 | E7: 结构/说明 | G7: IT元素 | H7: 以用户首次创建元素，由上到下，由左到右依次记录 | O7: 不适用 | P7: 原始文本逐项保留；未改变原意。
A8: SRC.IT元素.005 | B8: omnia agent字段对照文档-补全.xlsx | C8: IT元素 | D8: 5 | E8: 结构/说明 | F8: Application | G8: IT元素 | H8: 应用程序 | O8: 不适用 | P8: 原始文本逐项保留；未改变原意。
A9: SRC.IT元素.006 | B9: omnia agent字段对照文档-补全.xlsx | C9: IT元素 | D9: 6 | E9: 结构/说明 | F9: Application | G9: IT元素 | H9: Key | I9: 描述 | J9: 填写方式 | K9: 示例/默认值 | L9: 校验内容（非AI） | M9: 校验内容（AI） | O9: 不适用 | P9: 原始文本逐项保留；未改变原意。
A10: SRC.IT元素.007 | B10: omnia agent字段对照文档-补全.xlsx | C10: IT元素 | D10: 7 | E10: 字段 | F10: Application | G10: IT元素 | H10: ID | I10: 应用程序唯一键，系统必填 | J10: 用户必填 | K10: APP-金蝶系统 | L10: 1、是否填写 2、是否与其他活跃元素重名 3、是否与其他回收站内元素重名 | M10: 1、与之后的risk判断因素中描述的内容是否一致 | N10: P1.APP.IT.ELEMENT_ID | O10: 已映射 | P10: 原始文本逐项保留；未改变原意。
A11: SRC.IT元素.008 | B11: omnia agent字段对照文档-补全.xlsx | C11: IT元素 | D11: 8 | E11: 字段 | F11: Application | G11: IT元素 | H11: 名称 | I11: 可与ID一致，系统必填 | J11: agent代填 | K11: 与ID一致 | N11: P1.APP.IT.ELEMENT_NAME | O11: 已映射 | P11: 原始文本逐项保留；未改变原意。
A12: SRC.IT元素.009 | B12: omnia agent字段对照文档-补全.xlsx | C12: IT元素 | D12: 9 | E12: 字段 | F12: Application | G12: IT元素 | H12: 链接至工作区 | I12: 系统必填 | J12: 用户必填 | K12: TEST | L12: 1、工作区填写是否正确 | M12: 1、若存在与APP名称相似的工作区，可校验ID与工作区是否存在疑似冲突 | N12: P1.APP.IT.WORKSPACE | O12: 已映射 | P12: 原始文本逐项保留；未改变原意。
A13: SRC.IT元素.010 | B13: omnia agent字段对照文档-补全.xlsx | C13: IT元素 | D13: 10 | E13: 字段 | F13: Application | G13: IT元素 | H13: 描述 | I13: 选填 | J13: agent代填 | K13: 与ID一致 | N13: P1.APP.IT.DESCRIPTION | O13: 已映射 | P13: 原始文本逐项保留；未改变原意。
A14: SRC.IT元素.011 | B14: omnia agent字段对照文档-补全.xlsx | C14: IT元素 | D14: 11 | E14: 字段 | F14: Application | G14: IT元素 | H14: 与应用程序的相关性 | J14: agent代填 | K14: 不相关 | N14: P1.APP.IT.IS_RELEVANT | O14: 已映射 | P14: 原始文本逐项保留；未改变原意。
A15: SRC.IT元素.012 | B15: omnia agent字段对照文档-补全.xlsx | C15: IT元素 | D15: 12 | E15: 字段 | F15: Application | G15: IT元素 | H15: IT元素和相关信息技术整体控制(GITC) 将在此约定项目档案的结构化数据中进行测试 | I15: 创建的时候自动开启 | J15: 默认 | K15: 开启 | N15: P1.APP.IT.IS_DATA_AVAILABLE | O15: 已映射 | P15: 原始文本逐项保留；未改变原意。
A16: SRC.IT元素.013 | B16: omnia agent字段对照文档-补全.xlsx | C16: IT元素 | D16: 13 | E16: 字段 | F16: Application | G16: IT元素 | H16: 添加风险评估GRA | I16: 参见<GRA>-应用程序 | N16: P1.APP.IT.GRA_ENTRY | O16: 已映射 | P16: 原始文本逐项保留；未改变原意。
A17: SRC.IT元素.014 | B17: omnia agent字段对照文档-补全.xlsx | C17: IT元素 | D17: 14 | E17: 字段 | F17: Application | G17: IT元素 | H17: 详细信息-本年度重大修改 | I17: 考虑IT元素在本年度是否已发生重大变化 (例如，系统升级，新系统实施) 或修改。考虑变更的性质和变更的范围。 | J17: 默认 | K17: 不开启 | N17: P1.APP.IT.MAJOR_CHANGE_THIS_YEAR | O17: 已映射 | P17: 原始文本逐项保留；未改变原意。
A18: SRC.IT元素.015 | B18: omnia agent字段对照文档-补全.xlsx | C18: IT元素 | D18: 15 | E18: 字段 | F18: Application | G18: IT元素 | H18: 详细信息-受到服务机构支持（包括提供的服务，如适用） | I18: 考虑IT元素是否由向该主体提供服务的服务机构 (即，第三方组织或第三方组织的部门) 支持。 | J18: 默认 | K18: 不开启 | N18: P1.APP.IT.SERVICE_ORGANIZATION_SUPPORT | O18: 已映射 | P18: 原始文本逐项保留；未改变原意。
A19: SRC.IT元素.016 | B19: omnia agent字段对照文档-补全.xlsx | C19: IT元素 | D19: 16 | E19: 字段 | F19: Application | G19: IT元素 | H19: 详细信息-拟在测试中使用的德勤审计工具 | I19: 考虑在计划的IT元素测试中是否使用任何德勤工具 (如，ACTT)。请注意，在Omnia的当前版本中，位于此处的文件记录可协助您记录及保留有助于计划审计程序的信息，但此信息不会系统地与其他结构化数据链接或相关联。 | J19: 默认 | K19: 不开启 | N19: P1.APP.IT.DELOITTE_AUDIT_TOOL | O19: 已映射 | P19: 原始文本逐项保留；未改变原意。
A20: SRC.IT元素.017 | B20: omnia agent字段对照文档-补全.xlsx | C20: IT元素 | D20: 17 | E20: 字段 | F20: Application | G20: IT元素 | H20: 业务流程 | I20: 在业务流程图中关联此应用，此处不适用 | N20: P1.APP.IT.BUSINESS_PROCESS | O20: 已映射 | P20: 原始文本逐项保留；未改变原意。
A21: SRC.IT元素.019 | B21: omnia agent字段对照文档-补全.xlsx | C21: IT元素 | D21: 19 | E21: 结构/说明 | F21: Database Infrastructure | G21: IT元素 | H21: 基础设施（数据库 / DB） | O21: 不适用 | P21: 原始文本逐项保留；未改变原意。
A22: SRC.IT元素.020 | B22: omnia agent字段对照文档-补全.xlsx | C22: IT元素 | D22: 20 | E22: 结构/说明 | F22: Database Infrastructure | G22: IT元素 | H22: Key | I22: 描述 | J22: 填写方式 | K22: 示例/默认值 | L22: 校验内容（非AI） | M22: 校验内容（AI） | O22: 不适用 | P22: 原始文本逐项保留；未改变原意。
A23: SRC.IT元素.021 | B23: omnia agent字段对照文档-补全.xlsx | C23: IT元素 | D23: 21 | E23: 字段 | F23: Database Infrastructure | G23: IT元素 | H23: ID | I23: 数据库基础设施唯一键，系统必填 | J23: 用户必填 | K23: DB-金蝶系统 | L23: 1、是否填写 2、是否与其他活跃元素重名 3、是否与其他回收站内元素重名 | M23: 1、与之后的risk判断因素中描述的内容是否一致 | N23: P1.DB.IT.ELEMENT_ID | O23: 已映射 | P23: 原始文本逐项保留；未改变原意。
A24: SRC.IT元素.022 | B24: omnia agent字段对照文档-补全.xlsx | C24: IT元素 | D24: 22 | E24: 字段 | F24: Database Infrastructure | G24: IT元素 | H24: 名称 | I24: 可与ID一致，系统必填 | J24: agent代填 | K24: 与ID一致 | N24: P1.DB.IT.ELEMENT_NAME | O24: 已映射 | P24: 原始文本逐项保留；未改变原意。
A25: SRC.IT元素.023 | B25: omnia agent字段对照文档-补全.xlsx | C25: IT元素 | D25: 23 | E25: 字段 | F25: Database Infrastructure | G25: IT元素 | H25: 链接至工作区 | I25: 系统必填 | J25: 用户必填 | K25: TEST | L25: 1、工作区填写是否正确 | M25: 1、若存在与名称相似的工作区，可校验ID与工作区是否存在疑似冲突 | N25: P1.DB.IT.WORKSPACE | O25: 已映射 | P25: 原始文本逐项保留；未改变原意。
A26: SRC.IT元素.024 | B26: omnia agent字段对照文档-补全.xlsx | C26: IT元素 | D26: 24 | E26: 字段 | F26: Database Infrastructure | G26: IT元素 | H26: 描述 | I26: 选填 | J26: agent代填 | K26: 与ID一致 | N26: P1.DB.IT.DESCRIPTION | O26: 已映射 | P26: 原始文本逐项保留；未改变原意。
A27: SRC.IT元素.025 | B27: omnia agent字段对照文档-补全.xlsx | C27: IT元素 | D27: 25 | E27: 字段 | F27: Database Infrastructure | G27: IT元素 | H27: 与应用程序的相关性 | J27: agent代填 | K27: 不相关 | N27: P1.DB.IT.IS_RELEVANT | O27: 已映射 | P27: 原始文本逐项保留；未改变原意。
A28: SRC.IT元素.026 | B28: omnia agent字段对照文档-补全.xlsx | C28: IT元素 | D28: 26 | E28: 字段 | F28: Database Infrastructure | G28: IT元素 | H28: IT元素和相关信息技术整体控制(GITC) 将在此约定项目档案的结构化数据中进行测试 | I28: 创建的时候自动开启 | J28: 默认 | K28: 开启 | N28: P1.DB.IT.IS_DATA_AVAILABLE | O28: 已映射 | P28: 原始文本逐项保留；未改变原意。
A29: SRC.IT元素.027 | B29: omnia agent字段对照文档-补全.xlsx | C29: IT元素 | D29: 27 | E29: 字段 | F29: Database Infrastructure | G29: IT元素 | H29: 添加风险评估GRA | I29: 参见<GRA>-数据库 | N29: P1.DB.IT.GRA_ENTRY | O29: 已映射 | P29: 原始文本逐项保留；未改变原意。
A30: SRC.IT元素.028 | B30: omnia agent字段对照文档-补全.xlsx | C30: IT元素 | D30: 28 | E30: 字段 | F30: Database Infrastructure | G30: IT元素 | H30: 详细信息-本年度重大修改 | I30: 考虑IT元素在本年度是否已发生重大变化 (例如，系统升级，新系统实施) 或修改。考虑变更的性质和变更的范围。 | J30: 默认 | K30: 不开启 | N30: P1.DB.IT.MAJOR_CHANGE_THIS_YEAR | O30: 已映射 | P30: 原始文本逐项保留；未改变原意。
A31: SRC.IT元素.029 | B31: omnia agent字段对照文档-补全.xlsx | C31: IT元素 | D31: 29 | E31: 字段 | F31: Database Infrastructure | G31: IT元素 | H31: 详细信息-受到服务机构支持（包括提供的服务，如适用） | I31: 考虑IT元素是否由向该主体提供服务的服务机构 (即，第三方组织或第三方组织的部门) 支持。 | J31: 默认 | K31: 不开启 | N31: P1.DB.IT.SERVICE_ORGANIZATION_SUPPORT | O31: 已映射 | P31: 原始文本逐项保留；未改变原意。
A32: SRC.IT元素.030 | B32: omnia agent字段对照文档-补全.xlsx | C32: IT元素 | D32: 30 | E32: 字段 | F32: Database Infrastructure | G32: IT元素 | H32: 详细信息-拟在测试中使用的德勤审计工具 | I32: 考虑在计划的IT元素测试中是否使用任何德勤工具 (如，ACTT)。请注意，在Omnia的当前版本中，位于此处的文件记录可协助您记录及保留有助于计划审计程序的信息，但此信息不会系统地与其他结构化数据链接或相关联。 | J32: 默认 | K32: 不开启 | N32: P1.DB.IT.DELOITTE_AUDIT_TOOL | O32: 已映射 | P32: 原始文本逐项保留；未改变原意。
A33: SRC.IT元素.031 | B33: omnia agent字段对照文档-补全.xlsx | C33: IT元素 | D33: 31 | E33: 字段 | F33: Database Infrastructure | G33: IT元素 | H33: 关联应用程序 | I33: 后续创建风险评估受此影响，系统必填 | J33: 用户必填 | K33: APP-金蝶系统 | L33: 1、是否至少关联一个应用程序 2、工作区是否一致 3、多个应用程序的RAIT是否一致 | N33: P1.DB.IT.APPLICATION_RELATION | O33: 已映射 | P33: 原始文本逐项保留；未改变原意。
A34: SRC.IT元素.033 | B34: omnia agent字段对照文档-补全.xlsx | C34: IT元素 | D34: 33 | E34: 结构/说明 | F34: Operating System Infrastructure | G34: IT元素 | H34: 基础设施（操作系统 / OS） | O34: 不适用 | P34: 原始文本逐项保留；未改变原意。
A35: SRC.IT元素.034 | B35: omnia agent字段对照文档-补全.xlsx | C35: IT元素 | D35: 34 | E35: 结构/说明 | F35: Operating System Infrastructure | G35: IT元素 | H35: Key | I35: 描述 | J35: 填写方式 | K35: 示例/默认值 | L35: 校验内容（非AI） | M35: 校验内容（AI） | O35: 不适用 | P35: 原始文本逐项保留；未改变原意。
A36: SRC.IT元素.035 | B36: omnia agent字段对照文档-补全.xlsx | C36: IT元素 | D36: 35 | E36: 字段 | F36: Operating System Infrastructure | G36: IT元素 | H36: ID | I36: 操作系统基础设施唯一键，系统必填 | J36: 用户必填 | K36: OS-金蝶服务器 | L36: 1、是否填写 2、是否与其他活跃元素重名 3、是否与其他回收站内元素重名 | M36: 1、与之后的risk判断因素中描述的内容是否一致 | N36: P1.OS.IT.ELEMENT_ID | O36: 已映射 | P36: 原始文本逐项保留；未改变原意。
A37: SRC.IT元素.036 | B37: omnia agent字段对照文档-补全.xlsx | C37: IT元素 | D37: 36 | E37: 字段 | F37: Operating System Infrastructure | G37: IT元素 | H37: 名称 | I37: 可与ID一致，系统必填 | J37: agent代填 | K37: 与ID一致 | N37: P1.OS.IT.ELEMENT_NAME | O37: 已映射 | P37: 原始文本逐项保留；未改变原意。
A38: SRC.IT元素.037 | B38: omnia agent字段对照文档-补全.xlsx | C38: IT元素 | D38: 37 | E38: 字段 | F38: Operating System Infrastructure | G38: IT元素 | H38: 链接至工作区 | I38: 系统必填 | J38: 用户必填 | K38: TEST | L38: 1、工作区填写是否正确 | M38: 1、若存在与名称相似的工作区，可校验ID与工作区是否存在疑似冲突 | N38: P1.OS.IT.WORKSPACE | O38: 已映射 | P38: 原始文本逐项保留；未改变原意。
A39: SRC.IT元素.038 | B39: omnia agent字段对照文档-补全.xlsx | C39: IT元素 | D39: 38 | E39: 字段 | F39: Operating System Infrastructure | G39: IT元素 | H39: 描述 | I39: 选填；官方V2由Agent固定派生为元素ID | J39: agent代填 | K39: 与ID一致 | N39: P1.OS.IT.DESCRIPTION | O39: 已映射 | P39: 原始文本逐项保留；未改变原意。
A40: SRC.IT元素.039 | B40: omnia agent字段对照文档-补全.xlsx | C40: IT元素 | D40: 39 | E40: 字段 | F40: Operating System Infrastructure | G40: IT元素 | H40: 与应用程序的相关性 | J40: agent代填 | K40: 不相关 | N40: P1.OS.IT.IS_RELEVANT | O40: 已映射 | P40: 原始文本逐项保留；未改变原意。
A41: SRC.IT元素.040 | B41: omnia agent字段对照文档-补全.xlsx | C41: IT元素 | D41: 40 | E41: 字段 | F41: Operating System Infrastructure | G41: IT元素 | H41: IT元素和相关信息技术整体控制(GITC) 将在此约定项目档案的结构化数据中进行测试 | I41: 创建的时候自动开启 | J41: 默认 | K41: 开启 | N41: P1.OS.IT.IS_DATA_AVAILABLE | O41: 已映射 | P41: 原始文本逐项保留；未改变原意。
...

Sheet SAP ECC录制证据
A1: SAP ECC 创建录制｜API 与缺口证据
A2: 证据来源：dfa8eb76、f312280e、cfd09224，三份均为 v4 recorder 录制；本表仅保留接口结构、字段语义和脱敏计数，不复制对象 ID、邮箱、token 或原始敏感内容。
A4: evidence_id | B4: 动作/规则 | C4: 适用对象 | D4: method + endpoint | E4: request 字段 | F4: response/read-back 字段 | G4: 录制事件 | H4: 证据状态 | I4: 可支持的结论 | J4: 缺口/阻断 | K4: 修复/补录要求 | L4: 备注
A5: REC.SAP_ECC.TAXONOMY | B5: 识别 SAP ECC 内容身份 | C5: Application / SAP ECC | D5: GET /rapr/v0/engagements/{engagementId}/itelement/getITElementCategoryPublicationList | E5: 无业务 body | F5: taxonomy key=66176475；name=StandardizedAccount_SAP ECC | G5: request-25 / seq83 / HTTP 200 | H5: 录制已证实 | I5: 可确定当前录制中 SAP ECC 的内容键 | J5: 不是 Feature mutation canary，也未证明所有 Pack 永久相同 | K5: 运行时从当前 Pack 读 taxonomy 并按 key+name 唯一匹配 | L5: 禁止仅按 UI 文案或历史常量选择
A6: REC.SAP_ECC.CREATE_ELEMENT | B6: 创建 IT Element | C6: Application | D6: POST /rapr/v0/engagements/{engagementId}/itelement | E6: name, workspaceId, description, engagementId, number, itElementType=Application | F6: id, workItemId, itElementType；随后 GET detail | G6: request-29 / seq134 / HTTP 200 | H6: 录制已证实 | I6: 可形成窄 create-element Operation 候选 | J6: 请求未携带 SAP ECC subtype；类型身份来自后续 GRA 内容选择 | K6: 补充 exact preflight、重复/回收站检查、幂等、写后读回 canary | L6: 不宣称新建与关联 Feature 已可用
A7: REC.SAP_ECC.SET_RELEVANT | B7: 设置 IT Element 相关 | C7: Application | D7: PATCH /rapr/v0/engagements/{engagementId}/itelement/{id} | E7: JSON Patch /isRelevant=true, /concurrencyTabId=501, /concurrencyTabUpdatedOn | F7: isRelevant=true；concurrencyTabs 回读 | G7: request-132 / seq521 / HTTP 200 | H7: 录制已证实 | I7: 可形成窄 patch 候选 | J7: 仅覆盖当前录制字段 | K7: 冻结并发 token、before/read-back 与 response-loss 语义 | L7: 字段级证据，不代表整张设置页
A8: REC.SAP_ECC.CREATE_GRA | B8: 创建 SAP ECC GRA | C8: Application / SAP ECC | D8: POST /rapr/v0/engagements/{engagementId}/riskassessments/create | E8: inkContentId=66176475, typeId=3, facetId, entityId, name | F8: id, workItemId, referenceNumber, inkContentId；GET exact GRA | G8: request-135 / seq531 / HTTP 200；request-142/146 read-back | H8: 录制已证实 | I8: 可确认 SAP ECC GRA create payload 与核心 read-back 字段 | J8: 未覆盖风险因素评价、评分、“在此记录”文字写入、提交和 Risk-Control | K8: 补录完整评价链并做 signed Operation/read-back canary | L8: 当前只解除“SAP ECC GRA 内容/创建 API 未知”这一窄缺口
A9: REC.SAP_ECC.READ_GRA | B9: 读取 SAP ECC GRA 身份 | C9: Application / SAP ECC | D9: GET /rapr/v0/engagements/{engagementId}/riskassessments/{id} | E9: path id | F9: inkContentId=66176475；riskScopes.commonAccountName=SAP ECC；workItemId/referenceNumber/status | G9: request-142 / seq563；request-146 / seq579 / HTTP 200 | H9: 录制已证实 | I9: 可进行 GRA 身份/内容读回 | J9: 当时 status 仍在生成阶段；未有最终 EvaluationComplete | K9: 后续 mutation 后再次 exact read-back/poll | L9: 不得把 ContentPending/NotStarted 当完成
